<mujoco model="Kuka_KR6">
  <compiler angle="radian" autolimits="true"/>

  <option integrator="implicitfast" impratio="10"/>

  <default>
    <default class="panda">
      <material specular="0.5" shininess="0.25"/>
      <joint armature="0.1" damping="1" axis="0 0 1" range="-2.8973 2.8973"/>
      <general dyntype="none" biastype="affine" ctrlrange="-2.8973 2.8973" forcerange="-87 87"/>

      <default class="panda/visual">
        <geom type="mesh" contype="0" conaffinity="0" group="2"/>
      </default>
      <default class="panda/collision">
        <geom type="mesh" group="3"/>
      </default>
      <site size="0.001" rgba="0.5 0.5 0.5 0.3" group="4"/>
    </default>
  </default>

  <asset>

    <texture type="skybox" builtin="gradient" rgb1="0.3 0.5 0.7" rgb2="0 0 0" width="512" height="3072"/>
    <texture type="2d" name="groundplane" builtin="checker" mark="edge" rgb1="0.2 0.3 0.4" rgb2="0.1 0.2 0.3"
      markrgb="0.8 0.8 0.8" width="300" height="300"/>
    <material name="groundplane" texture="groundplane" texuniform="true" texrepeat="5 5" reflectance="0.2"/>

    <material class="panda" name="white" rgba="1.0 0.4 0.0 1.0"/>
    <material class="panda" name="off_white" rgba="0 0 0 1"/>
    <material class="panda" name="dark_grey" rgba="0.45 0.45 0.45 1"/>
    <material class="panda" name="green" rgba="0 1 0 1"/>
    <material class="panda" name="light_blue" rgba="0.039216 0.541176 0.780392 1"/>

    <!-- Collision meshes -->
    <mesh name="link0_c" file="meshes/collision/base_link.stl"/>
    <mesh name="link1_c" file="meshes/collision/link_1.stl"/>
    <mesh name="link2_c" file="meshes/collision/link_2.stl"/>
    <mesh name="link3_c" file="meshes/collision/link_3.stl"/>
    <mesh name="link4_c" file="meshes/collision/link_4.stl"/>
    <mesh name="link5_c" file="meshes/collision/link_5.stl"/>
    <mesh name="link6_c" file="meshes/collision/link_6.stl"/>
    <mesh name="linkee_c" file="meshes/collision/end_effector.stl" scale="0.001 0.001 0.001"/>
    
    <mesh name="link0" file="meshes/visual/base_link.stl"/>
    <mesh name="link1" file="meshes/visual/link_1.stl"/>
    <mesh name="link2" file="meshes/visual/link_2.stl"/>
    <mesh name="link3" file="meshes/visual/link_3.stl"/>
    <mesh name="link4" file="meshes/visual/link_4.stl"/>
    <mesh name="link5" file="meshes/visual/link_5.stl"/>
    <mesh name="link6" file="meshes/visual/link_6.stl"/>
    <mesh name="linkee" file="meshes/visual/end_effector.stl" scale="0.001 0.001 0.001"/>

    
  </asset>

  <worldbody>
    <light name="top" pos="0 0 10" mode="trackcom"/>
    <geom name="floor" size="0 0 0.05" type="plane" material="groundplane" contype="1"/>
    <body name="workpiece" childclass="panda">
      <geom type="box" size="0.1 0.2 0.01" pos="0.59 0 0" density="1000" />
      <geom type="box" size="0.1 0.2 0.01" pos="0.81 0 0" density="1000" />
    </body>
    <body name="link0" childclass="panda">
      <inertial mass="0.629769" pos="-0.041018 -0.00014 0.049974"
        fullinertia="0.00315 0.00388 0.004285 8.2904e-7 0.00015 8.2299e-6"/>
      <geom mesh="link0" material="off_white" class="panda/visual"/>
      <geom mesh="link0_c" class="panda/collision"/>
      <body name="link1" pos="0 0 0.4" quat="1 0 0 0">
        <inertial mass="4.970684" pos="0.003875 0.002081 -0.04762"
          fullinertia="0.70337 0.70661 0.0091170 -0.00013900 0.0067720 0.019169"/>
        <joint name="joint1" axis="0 0 -1"/>
        <geom material="white" mesh="link1" class="panda/visual"/>
        <geom mesh="link1_c" class="panda/collision"/>
        <body name="link2" pos="0.025 0 0" quat="1 0 0 0">
          <inertial mass="0.646926" pos="-0.003141 -0.02872 0.003495"
            fullinertia="0.0079620 2.8110e-2 2.5995e-2 -3.925e-3 1.0254e-2 7.04e-4"/>
          <joint name="joint2" axis="0 1 0" range="-1.7628 1.7628" ref="1.5708"/>
          <geom material="white" mesh="link2" class="panda/visual"/>
          <geom mesh="link2_c" class="panda/collision"/>
          <body name="link3" pos="0.315 0 0" quat="1 0 0 0">
            <joint name="joint3" axis="0 1 0" ref="-1.5708"/>
            <inertial mass="3.228604" pos="2.7518e-2 3.9252e-2 -6.6502e-2"
              fullinertia="3.7242e-2 3.6155e-2 1.083e-2 -4.761e-3 -1.1396e-2 -1.2805e-2"/>
            <geom mesh="link3" material="white" class="panda/visual"/>
            <geom mesh="link3_c" class="panda/collision"/>
            <body name="link4" pos="0 0 0.035" quat="1 0 0 0">
              <inertial mass="3.587895" pos="-5.317e-2 1.04419e-1 2.7454e-2"
                fullinertia="2.5853e-2 1.9552e-2 2.8323e-2 7.796e-3 -1.332e-3 8.641e-3"/>
              <joint name="joint4" axis="1 0 0" range="-3.0718 -0.0698"/>
              <geom mesh="link4" material="white" class="panda/visual"/>
              <geom mesh="link4_c" class="panda/collision"/>
              <body name="link5" pos="0.365 0 0" quat="1 0 0 0">
                <inertial mass="1.225946" pos="-1.1953e-2 4.1065e-2 -3.8437e-2"
                  fullinertia="3.5549e-2 2.9474e-2 8.627e-3 -2.117e-3 -4.037e-3 2.29e-4"/>
                <joint name="joint5" axis="0 1 0"/>
                <geom mesh="link5" material="dark_grey" class="panda/visual"/>
                <geom mesh="link5_c" class="panda/collision"/>
                <body name="link6" pos="0.080 0 0" quat="1 0 0 0">
                  <inertial mass="1.666555" pos="6.0149e-2 -1.4117e-2 -1.0517e-2"
                    fullinertia="1.964e-3 4.354e-3 5.433e-3 1.09e-4 -1.158e-3 3.41e-4"/>
                  <joint name="joint6" axis="-1 0 0" range="-0.0175 3.7525" ref="-1.5708"/>
                  <geom mesh="link6" material="off_white" class="panda/visual"/>
                  <geom mesh="link6_c" class="panda/collision"/>
                  <body name="linkee" pos="0 0 0" quat="0.5 0.5 0.5 0.5">
                    <inertial mass="7.35522e-01" pos="1.0517e-2 -4.252e-3 6.1597e-2"
                      fullinertia="1.2516e-2 1.0027e-2 4.815e-3 -4.28e-4 -1.196e-3 -7.41e-4"/>
                    <geom mesh="linkee" material="white" class="panda/visual"/>
                    <geom mesh="linkee_c" class="panda/collision"/>
                    <body name="translated_frame" pos="0.065 0 0.25"  quat="0.9397 0 0.3420 0">
                    </body>
                  </body>
                </body>
              </body>
            </body>
          </body>
        </body>
      </body>
    </body>
  </worldbody>

  <actuator>
    <general class="panda" name="actuator1" joint="joint1" gainprm="4500" biasprm="0 -4500 -450" ctrlrange="-1.7628 1.7628"/>
    <general class="panda" name="actuator2" joint="joint2" gainprm="4500" biasprm="0 -4500 -450"
      ctrlrange="-1.7628 1.7628"/>
    <general class="panda" name="actuator3" joint="joint3" gainprm="3500" biasprm="0 -3500 -350"/>
    <general class="panda" name="actuator4" joint="joint4" gainprm="3500" biasprm="0 -3500 -350"
      ctrlrange="-3.0718 -0.0698"/>
    <general class="panda" name="actuator5" joint="joint5" gainprm="2000" biasprm="0 -2000 -200" forcerange="-12 12"/>
    <general class="panda" name="actuator6" joint="joint6" gainprm="4000" biasprm="0 -2000 -200" forcerange="-12 12"
      ctrlrange="-0.0175 3.7525"/>
  </actuator>

  
</mujoco>
